<?xml version="1.0" encoding="UTF-8"?>
<testng-results ignored="0" total="2" passed="2" failed="0" skipped="0">
  <reporter-output>
  </reporter-output>
  <suite started-at="2020-11-01T15:08:22Z" name="测试套件: " finished-at="2020-11-01T15:08:22Z" duration-ms="45">
    <groups>
    </groups>
    <test started-at="2020-11-01T15:08:22Z" name="test" finished-at="2020-11-01T15:08:22Z" duration-ms="45">
      <class name="com.testng.exceptions.ExpectedExceptionTest">
        <test-method signature="testPrintMessage()[pri:0, instance:com.testng.exceptions.ExpectedExceptionTest@be64738]" started-at="2020-11-01T23:08:22Z" name="testPrintMessage" finished-at="2020-11-01T23:08:22Z" duration-ms="20" status="PASS">
          <exception class="java.lang.ArithmeticException">
            <message>
              <![CDATA[/ by zero]]>
            </message>
            <full-stacktrace>
              <![CDATA[java.lang.ArithmeticException: / by zero
	at com.testng.exceptions.MessageUtil.printMessage(MessageUtil.java:13)
	at com.testng.exceptions.ExpectedExceptionTest.testPrintMessage(ExpectedExceptionTest.java:13)
	at java.base/jdk.internal.reflect.NativeMethodAccessorImpl.invoke0(Native Method)
	at java.base/jdk.internal.reflect.NativeMethodAccessorImpl.invoke(NativeMethodAccessorImpl.java:62)
	at java.base/jdk.internal.reflect.DelegatingMethodAccessorImpl.invoke(DelegatingMethodAccessorImpl.java:43)
	at java.base/java.lang.reflect.Method.invoke(Method.java:564)
	at org.testng.internal.MethodInvocationHelper.invokeMethod(MethodInvocationHelper.java:104)
	at org.testng.internal.Invoker.invokeMethod(Invoker.java:645)
	at org.testng.internal.Invoker.invokeTestMethod(Invoker.java:851)
	at org.testng.internal.Invoker.invokeTestMethods(Invoker.java:1177)
	at org.testng.internal.TestMethodWorker.invokeTestMethods(TestMethodWorker.java:129)
	at org.testng.internal.TestMethodWorker.run(TestMethodWorker.java:112)
	at org.testng.TestRunner.privateRun(TestRunner.java:756)
	at org.testng.TestRunner.run(TestRunner.java:610)
	at org.testng.SuiteRunner.runTest(SuiteRunner.java:387)
	at org.testng.SuiteRunner.runSequentially(SuiteRunner.java:382)
	at org.testng.SuiteRunner.privateRun(SuiteRunner.java:340)
	at org.testng.SuiteRunner.run(SuiteRunner.java:289)
	at org.testng.SuiteRunnerWorker.runSuite(SuiteRunnerWorker.java:52)
	at org.testng.SuiteRunnerWorker.run(SuiteRunnerWorker.java:86)
	at org.testng.TestNG.runSuitesSequentially(TestNG.java:1293)
	at org.testng.TestNG.runSuitesLocally(TestNG.java:1218)
	at org.testng.TestNG.runSuites(TestNG.java:1133)
	at org.testng.TestNG.run(TestNG.java:1104)
	at com.intellij.rt.testng.IDEARemoteTestNG.run(IDEARemoteTestNG.java:66)
	at com.intellij.rt.testng.RemoteTestNGStarter.main(RemoteTestNGStarter.java:109)
]]>
            </full-stacktrace>
          </exception> <!-- java.lang.ArithmeticException -->
          <reporter-output>
          </reporter-output>
        </test-method> <!-- testPrintMessage -->
        <test-method signature="testSalutationMessage()[pri:0, instance:com.testng.exceptions.ExpectedExceptionTest@be64738]" started-at="2020-11-01T23:08:22Z" name="testSalutationMessage" finished-at="2020-11-01T23:08:22Z" duration-ms="3" status="PASS">
          <reporter-output>
          </reporter-output>
        </test-method> <!-- testSalutationMessage -->
      </class> <!-- com.testng.exceptions.ExpectedExceptionTest -->
    </test> <!-- test -->
  </suite> <!-- 测试套件:  -->
</testng-results>
